<?xml version="1.0" encoding="utf-8"?><testsuites><testsuite name="pytest" errors="0" failures="8" skipped="0" tests="8" time="50.100" timestamp="2020-11-19T11:12:21.394809" hostname="doron-VirtualBox"><testcase classname="DataBaseTest.tests.crm_tables.test_crm_pricebook.price_book_Test" name="test_crm_price_book_ecommerce_flag" time="2.791"><failure message="assert 1 == 0">crm_tables/test_crm_pricebook.py:27: in test_crm_price_book_ecommerce_flag
    assert 1 == comper_beween_data_frame.is_test_failed(comper_result, crm_ecommerce_flag_df,
E   assert 1 == 0</failure></testcase><testcase classname="DataBaseTest.tests.crm_tables.test_crm_pricebook.price_book_Test" name="test_crm_price_book_created_user_name" time="0.197"><failure message="assert 1 == 0">crm_tables/test_crm_pricebook.py:47: in test_crm_price_book_created_user_name
    assert 1 == comper_beween_data_frame.is_test_failed(comper_result, crm_created_user_name_df,
E   assert 1 == 0</failure></testcase><testcase classname="DataBaseTest.tests.crm_tables.test_crm_pricebook.price_book_Test" name="test_crm_price_book_updated_user_name" time="0.150"><failure message="assert 1 == 0">crm_tables/test_crm_pricebook.py:67: in test_crm_price_book_updated_user_name
    assert 1 == comper_beween_data_frame.is_test_failed(comper_result, crm_created_user_name_df,
E   assert 1 == 0</failure></testcase><testcase classname="DataBaseTest.tests.crm_tables.test_crm_pricebook.price_book_Test" name="test_crm_price_book_full_table" time="0.269"><failure message="FileNotFoundError: [Errno 2] No such file or directory: '/home/doron/PycharmProjects/pythonProject/DataBaseTest/crm_tables/crm_result_directory/price_book_11-19-2020,11:12:25result.txt'">crm_tables/test_crm_pricebook.py:80: in test_crm_price_book_full_table
    comper_beween_data_frame.write_test_result_to_file(data_config.log_directory['crm_table'] + "/price_book",
../helper_fanctions/comper_beween_data_frame.py:25: in write_test_result_to_file
    with open(file_name + '_' + date_time + 'result.txt', 'a') as resultSummary:
E   FileNotFoundError: [Errno 2] No such file or directory: '/home/doron/PycharmProjects/pythonProject/DataBaseTest/crm_tables/crm_result_directory/price_book_11-19-2020,11:12:25result.txt'</failure></testcase><testcase classname="DataBaseTest.tests.crm_tables.test_crm_sps.crm_sps_Test" name="test_sps_customer_ownership_flag" time="2.792"><failure message="assert 1 == 0">/home/doron/PycharmProjects/pythonProject/DataBaseTest/crm_tables/test_crm_sps.py:23: in test_sps_customer_ownership_flag
    ???
E   assert 1 == 0</failure></testcase><testcase classname="DataBaseTest.tests.crm_tables.test_crm_sps.crm_sps_Test" name="test_sps_curr_panel1_wattage" time="2.259"><failure message="KeyError: &quot;['curr_panel1_wattage'] not in index&quot;">/home/doron/PycharmProjects/pythonProject/DataBaseTest/crm_tables/test_crm_sps.py:37: in test_sps_curr_panel1_wattage
    ???
../../venv/lib/python3.8/site-packages/pandas/core/frame.py:2908: in __getitem__
    indexer = self.loc._get_listlike_indexer(key, axis=1, raise_missing=True)[1]
../../venv/lib/python3.8/site-packages/pandas/core/indexing.py:1254: in _get_listlike_indexer
    self._validate_read_indexer(keyarr, indexer, axis, raise_missing=raise_missing)
../../venv/lib/python3.8/site-packages/pandas/core/indexing.py:1304: in _validate_read_indexer
    raise KeyError(f"{not_found} not in index")
E   KeyError: "['curr_panel1_wattage'] not in index"</failure></testcase><testcase classname="DataBaseTest.tests.crm_tables.test_crm_sps.crm_sps_Test" name="test_sps_curr_panel2_wattage" time="0.043"><failure message="KeyError: &quot;['curr_panel2_wattage'] not in index&quot;">/home/doron/PycharmProjects/pythonProject/DataBaseTest/crm_tables/test_crm_sps.py:56: in test_sps_curr_panel2_wattage
    ???
../../venv/lib/python3.8/site-packages/pandas/core/frame.py:2908: in __getitem__
    indexer = self.loc._get_listlike_indexer(key, axis=1, raise_missing=True)[1]
../../venv/lib/python3.8/site-packages/pandas/core/indexing.py:1254: in _get_listlike_indexer
    self._validate_read_indexer(keyarr, indexer, axis, raise_missing=raise_missing)
../../venv/lib/python3.8/site-packages/pandas/core/indexing.py:1304: in _validate_read_indexer
    raise KeyError(f"{not_found} not in index")
E   KeyError: "['curr_panel2_wattage'] not in index"</failure></testcase><testcase classname="DataBaseTest.tests.crm_tables.test_crm_sps.crm_sps_Test" name="test_sps_full_table" time="0.333"><failure message="assert 1 == 0">/home/doron/PycharmProjects/pythonProject/DataBaseTest/crm_tables/test_crm_sps.py:73: in test_sps_full_table
    ???
E   assert 1 == 0</failure></testcase></testsuite></testsuites>